<sdf version='1.6'>
  <model name='hithand'>
    <link name='base_link_hithand'>
      <pose frame=''>0 0 0.1 0 -0 0</pose>
      <inertial>
        <pose frame=''>0 0 0.05 0 -0 0</pose>
        <mass>1</mass>
        <inertia>
          <ixx>0.001</ixx>
          <ixy>0</ixy>
          <ixz>0</ixz>
          <iyy>0.001</iyy>
          <iyz>0</iyz>
          <izz>0.001</izz>
        </inertia>
      </inertial>
      <collision name='base_link_hithand_collision'>
        <pose frame=''>0 0 0 0 -0 0</pose>
        <geometry>
          <mesh>
            <scale>1 1 1</scale>
            <uri>model://hithand_description/meshes/collision/palm/hit-hand-2-palm-right.dae</uri>
          </mesh>
        </geometry>
        <surface>
          <contact>
            <ode/>
          </contact>
          <friction>
            <ode>
              <mu>1</mu>
              <mu2>1</mu2>
            </ode>
          </friction>
        </surface>
      </collision>
      <visual name='base_link_hithand_visual'>
        <pose frame=''>0 0 0 0 -0 0</pose>
        <geometry>
          <mesh>
            <scale>1 1 1</scale>
            <uri>model://hithand_description/meshes/visual/palm/hit-hand-2-palm-right.dae</uri>
          </mesh>
        </geometry>
        <material>
          <script>
            <uri>__default__</uri>
            <name>__default__</name>
          </script>
        </material>
      </visual>
      <gravity>1</gravity>
      <velocity_decay/>
      <self_collide>0</self_collide>
    </link>
    <joint name='fixed' type='fixed'>
      <child>base_link_hithand</child>
      <parent>world</parent>
    </joint>
    <link name='Right_Index_Basecover'>
      <pose frame=''>-0.00253 0.0368 0.207784 -0.087263 -1.57079 3.14159</pose>
      <inertial>
        <pose frame=''>0.02749 0 0 0 -0 0</pose>
        <mass>0.0176</mass>
        <inertia>
          <ixx>2e-06</ixx>
          <ixy>0</ixy>
          <ixz>0</ixz>
          <iyy>2e-06</iyy>
          <iyz>0</iyz>
          <izz>2e-06</izz>
        </inertia>
      </inertial>
      <collision name='Right_Index_Basecover_collision'>
        <pose frame=''>0 0 0 0 -0 0</pose>
        <geometry>
          <cylinder>
            <length>0.001</length>
            <radius>0.001</radius>
          </cylinder>
        </geometry>
        <surface>
          <contact>
            <ode/>
          </contact>
          <friction>
            <ode>
              <mu>1</mu>
              <mu2>1</mu2>
            </ode>
          </friction>
        </surface>
      </collision>
      <visual name='Right_Index_Basecover_visual'>
        <pose frame=''>0 0 0 0 -0 0</pose>
        <geometry>
          <mesh>
            <scale>1 1 1</scale>
            <uri>model://hithand_description/meshes/visual/hit-hand-2-finger-basecover.dae</uri>
          </mesh>
        </geometry>
        <material>
          <script>
            <uri>__default__</uri>
            <name>__default__</name>
          </script>
        </material>
      </visual>
      <gravity>1</gravity>
      <velocity_decay/>
      <self_collide>0</self_collide>
    </link>
    <joint name='Right_Index_0' type='revolute'>
      <child>Right_Index_Basecover</child>
      <parent>base_link_hithand</parent>
      <axis>
        <xyz>0.996195 -0.087156 -0</xyz>
        <limit>
          <lower>-0.261799</lower>
          <upper>0.261799</upper>
          <effort>15</effort>
          <velocity>3.14</velocity>
        </limit>
        <dynamics>
          <damping>0.7</damping>
          <friction>0.5</friction>
          <spring_reference>0</spring_reference>
          <spring_stiffness>0</spring_stiffness>
        </dynamics>
        <use_parent_model_frame>1</use_parent_model_frame>
      </axis>
    </joint>
    <link name='Right_Index_Phaprox'>
      <pose frame=''>-0.00253 0.0368 0.207784 1.48353 -1.57079 3.14159</pose>
      <inertial>
        <pose frame=''>0.02749 0 0 0 -0 0</pose>
        <mass>0.0232</mass>
        <inertia>
          <ixx>2e-06</ixx>
          <ixy>0</ixy>
          <ixz>0</ixz>
          <iyy>2e-06</iyy>
          <iyz>0</iyz>
          <izz>2e-06</izz>
        </inertia>
      </inertial>
      <collision name='Right_Index_Phaprox_collision'>
        <pose frame=''>0 0 0 0 -0 0</pose>
        <geometry>
          <mesh>
            <scale>1 1 1</scale>
            <uri>model://hithand_description/meshes/collision/finger/hit-hand-2-finger-phaprox.dae</uri>
          </mesh>
        </geometry>
        <surface>
          <contact>
            <ode/>
          </contact>
          <friction>
            <ode>
              <mu>1</mu>
              <mu2>1</mu2>
            </ode>
          </friction>
        </surface>
      </collision>
      <visual name='Right_Index_Phaprox_visual'>
        <pose frame=''>0 0 0 0 -0 0</pose>
        <geometry>
          <mesh>
            <scale>1 1 1</scale>
            <uri>model://hithand_description/meshes/visual/hit-hand-2-finger-phaprox.dae</uri>
          </mesh>
        </geometry>
        <material>
          <script>
            <uri>__default__</uri>
            <name>__default__</name>
          </script>
        </material>
      </visual>
      <gravity>1</gravity>
      <velocity_decay/>
      <self_collide>0</self_collide>
    </link>
    <joint name='Right_Index_1' type='revolute'>
      <child>Right_Index_Phaprox</child>
      <parent>Right_Index_Basecover</parent>
      <axis>
        <xyz>0.087152 0.996195 -0</xyz>
        <limit>
          <lower>0</lower>
          <upper>1.48353</upper>
          <effort>15</effort>
          <velocity>3.14</velocity>
        </limit>
        <dynamics>
          <damping>0.7</damping>
          <friction>0.5</friction>
          <spring_reference>0</spring_reference>
          <spring_stiffness>0</spring_stiffness>
        </dynamics>
        <use_parent_model_frame>1</use_parent_model_frame>
      </axis>
    </joint>
    <link name='Right_Index_Phamed'>
      <pose frame=''>-0.00253 0.0368 0.262784 1.48353 -1.57079 3.14159</pose>
      <inertial>
        <pose frame=''>0.0025 0 0 0 -0 0</pose>
        <mass>0.0158</mass>
        <inertia>
          <ixx>1e-06</ixx>
          <ixy>0</ixy>
          <ixz>0</ixz>
          <iyy>1e-06</iyy>
          <iyz>0</iyz>
          <izz>1e-06</izz>
        </inertia>
      </inertial>
      <collision name='Right_Index_Phamed_collision'>
        <pose frame=''>0 0 0 0 -0 0</pose>
        <geometry>
          <mesh>
            <scale>1 1 1</scale>
            <uri>model://hithand_description/meshes/collision/finger/hit-hand-2-finger-phamed.dae</uri>
          </mesh>
        </geometry>
        <surface>
          <contact>
            <ode/>
          </contact>
          <friction>
            <ode>
              <mu>1</mu>
              <mu2>1</mu2>
            </ode>
          </friction>
        </surface>
      </collision>
      <visual name='Right_Index_Phamed_visual'>
        <pose frame=''>0 0 0 0 -0 0</pose>
        <geometry>
          <mesh>
            <scale>1 1 1</scale>
            <uri>model://hithand_description/meshes/visual/hit-hand-2-finger-phamed.dae</uri>
          </mesh>
        </geometry>
        <material>
          <script>
            <uri>__default__</uri>
            <name>__default__</name>
          </script>
        </material>
      </visual>
      <gravity>1</gravity>
      <velocity_decay/>
      <self_collide>0</self_collide>
    </link>
    <joint name='Right_Index_2' type='revolute'>
      <child>Right_Index_Phamed</child>
      <parent>Right_Index_Phaprox</parent>
      <axis>
        <xyz>0.087152 0.996195 -0</xyz>
        <limit>
          <lower>0</lower>
          <upper>1.13446</upper>
          <effort>15</effort>
          <velocity>3.14</velocity>
        </limit>
        <dynamics>
          <damping>0.7</damping>
          <friction>0.5</friction>
          <spring_reference>0</spring_reference>
          <spring_stiffness>0</spring_stiffness>
        </dynamics>
        <use_parent_model_frame>1</use_parent_model_frame>
      </axis>
    </joint>
    <link name='Right_Index_Phadist'>
      <pose frame=''>-0.00253 0.0368 0.287784 1.5708 -0.000797 3.05433</pose>
      <inertial>
        <pose frame=''>0.003 0 0 0 -0 0</pose>
        <mass>0.0137</mass>
        <inertia>
          <ixx>1e-06</ixx>
          <ixy>0</ixy>
          <ixz>0</ixz>
          <iyy>1e-06</iyy>
          <iyz>0</iyz>
          <izz>1e-06</izz>
        </inertia>
      </inertial>
      <collision name='Right_Index_Phadist_collision'>
        <pose frame=''>0 0 0 0 -0 0</pose>
        <geometry>
          <mesh>
            <scale>1 1 1</scale>
            <uri>model://hithand_description/meshes/collision/finger/hit-hand-2-finger-phadist.dae</uri>
          </mesh>
        </geometry>
        <surface>
          <contact>
            <ode/>
          </contact>
          <friction>
            <ode>
              <mu>1</mu>
              <mu2>1</mu2>
            </ode>
          </friction>
        </surface>
      </collision>
      <visual name='Right_Index_Phadist_visual'>
        <pose frame=''>0 0 0 0 -0 0</pose>
        <geometry>
          <mesh>
            <scale>1 1 1</scale>
            <uri>model://hithand_description/meshes/visual/hit-hand-2-finger-phadist.dae</uri>
          </mesh>
        </geometry>
        <material>
          <script>
            <uri>__default__</uri>
            <name>__default__</name>
          </script>
        </material>
      </visual>
      <gravity>1</gravity>
      <velocity_decay/>
      <self_collide>0</self_collide>
    </link>
    <joint name='Right_Index_3' type='revolute'>
      <child>Right_Index_Phadist</child>
      <parent>Right_Index_Phamed</parent>
      <axis>
        <xyz>0.087152 0.996195 -0</xyz>
        <limit>
          <lower>-0.5</lower>
          <upper>1.4</upper>
          <effort>15</effort>
          <velocity>3.14</velocity>
        </limit>
        <dynamics>
          <damping>0.7</damping>
          <friction>0.5</friction>
          <spring_reference>0</spring_reference>
          <spring_stiffness>0</spring_stiffness>
        </dynamics>
        <use_parent_model_frame>1</use_parent_model_frame>
      </axis>
    </joint>
    <link name='Right_Little_Basecover'>
      <pose frame=''>0.000972 -0.043396 0.193584 0.174533 -1.57079 3.14159</pose>
      <inertial>
        <pose frame=''>0.02749 0 0 0 -0 0</pose>
        <mass>0.0176</mass>
        <inertia>
          <ixx>2e-06</ixx>
          <ixy>0</ixy>
          <ixz>0</ixz>
          <iyy>2e-06</iyy>
          <iyz>0</iyz>
          <izz>2e-06</izz>
        </inertia>
      </inertial>
      <collision name='Right_Little_Basecover_collision'>
        <pose frame=''>0 0 0 0 -0 0</pose>
        <geometry>
          <cylinder>
            <length>0.001</length>
            <radius>0.001</radius>
          </cylinder>
        </geometry>
        <surface>
          <contact>
            <ode/>
          </contact>
          <friction>
            <ode>
              <mu>1</mu>
              <mu2>1</mu2>
            </ode>
          </friction>
        </surface>
      </collision>
      <visual name='Right_Little_Basecover_visual'>
        <pose frame=''>0 0 0 0 -0 0</pose>
        <geometry>
          <mesh>
            <scale>1 1 1</scale>
            <uri>model://hithand_description/meshes/visual/hit-hand-2-finger-basecover.dae</uri>
          </mesh>
        </geometry>
        <material>
          <script>
            <uri>__default__</uri>
            <name>__default__</name>
          </script>
        </material>
      </visual>
      <gravity>1</gravity>
      <velocity_decay/>
      <self_collide>0</self_collide>
    </link>
    <joint name='Right_Little_0' type='revolute'>
      <child>Right_Little_Basecover</child>
      <parent>base_link_hithand</parent>
      <axis>
        <xyz>0.984808 0.173648 -0</xyz>
        <limit>
          <lower>-0.261799</lower>
          <upper>0.261799</upper>
          <effort>15</effort>
          <velocity>3.14</velocity>
        </limit>
        <dynamics>
          <damping>0.7</damping>
          <friction>0.5</friction>
          <spring_reference>0</spring_reference>
          <spring_stiffness>0</spring_stiffness>
        </dynamics>
        <use_parent_model_frame>1</use_parent_model_frame>
      </axis>
    </joint>
    <link name='Right_Little_Phaprox'>
      <pose frame=''>0.000972 -0.043396 0.193584 1.74533 -1.57079 3.14159</pose>
      <inertial>
        <pose frame=''>0.02749 0 0 0 -0 0</pose>
        <mass>0.0232</mass>
        <inertia>
          <ixx>2e-06</ixx>
          <ixy>0</ixy>
          <ixz>0</ixz>
          <iyy>2e-06</iyy>
          <iyz>0</iyz>
          <izz>2e-06</izz>
        </inertia>
      </inertial>
      <collision name='Right_Little_Phaprox_collision'>
        <pose frame=''>0 0 0 0 -0 0</pose>
        <geometry>
          <mesh>
            <scale>1 1 1</scale>
            <uri>model://hithand_description/meshes/collision/finger/hit-hand-2-finger-phaprox.dae</uri>
          </mesh>
        </geometry>
        <surface>
          <contact>
            <ode/>
          </contact>
          <friction>
            <ode>
              <mu>1</mu>
              <mu2>1</mu2>
            </ode>
          </friction>
        </surface>
      </collision>
      <visual name='Right_Little_Phaprox_visual'>
        <pose frame=''>0 0 0 0 -0 0</pose>
        <geometry>
          <mesh>
            <scale>1 1 1</scale>
            <uri>model://hithand_description/meshes/visual/hit-hand-2-finger-phaprox.dae</uri>
          </mesh>
        </geometry>
        <material>
          <script>
            <uri>__default__</uri>
            <name>__default__</name>
          </script>
        </material>
      </visual>
      <gravity>1</gravity>
      <velocity_decay/>
      <self_collide>0</self_collide>
    </link>
    <joint name='Right_Little_1' type='revolute'>
      <child>Right_Little_Phaprox</child>
      <parent>Right_Little_Basecover</parent>
      <axis>
        <xyz>-0.173652 0.984807 0</xyz>
        <limit>
          <lower>0</lower>
          <upper>1.48353</upper>
          <effort>15</effort>
          <velocity>3.14</velocity>
        </limit>
        <dynamics>
          <damping>0.7</damping>
          <friction>0.5</friction>
          <spring_reference>0</spring_reference>
          <spring_stiffness>0</spring_stiffness>
        </dynamics>
        <use_parent_model_frame>1</use_parent_model_frame>
      </axis>
    </joint>
    <link name='Right_Little_Phamed'>
      <pose frame=''>0.000972 -0.043396 0.248584 1.74533 -1.57079 3.14159</pose>
      <inertial>
        <pose frame=''>0.0025 0 0 0 -0 0</pose>
        <mass>0.0158</mass>
        <inertia>
          <ixx>1e-06</ixx>
          <ixy>0</ixy>
          <ixz>0</ixz>
          <iyy>1e-06</iyy>
          <iyz>0</iyz>
          <izz>1e-06</izz>
        </inertia>
      </inertial>
      <collision name='Right_Little_Phamed_collision'>
        <pose frame=''>0 0 0 0 -0 0</pose>
        <geometry>
          <mesh>
            <scale>1 1 1</scale>
            <uri>model://hithand_description/meshes/collision/finger/hit-hand-2-finger-phamed.dae</uri>
          </mesh>
        </geometry>
        <surface>
          <contact>
            <ode/>
          </contact>
          <friction>
            <ode>
              <mu>1</mu>
              <mu2>1</mu2>
            </ode>
          </friction>
        </surface>
      </collision>
      <visual name='Right_Little_Phamed_visual'>
        <pose frame=''>0 0 0 0 -0 0</pose>
        <geometry>
          <mesh>
            <scale>1 1 1</scale>
            <uri>model://hithand_description/meshes/visual/hit-hand-2-finger-phamed.dae</uri>
          </mesh>
        </geometry>
        <material>
          <script>
            <uri>__default__</uri>
            <name>__default__</name>
          </script>
        </material>
      </visual>
      <gravity>1</gravity>
      <velocity_decay/>
      <self_collide>0</self_collide>
    </link>
    <joint name='Right_Little_2' type='revolute'>
      <child>Right_Little_Phamed</child>
      <parent>Right_Little_Phaprox</parent>
      <axis>
        <xyz>-0.173652 0.984807 0</xyz>
        <limit>
          <lower>0</lower>
          <upper>1.13446</upper>
          <effort>15</effort>
          <velocity>3.14</velocity>
        </limit>
        <dynamics>
          <damping>0.7</damping>
          <friction>0.5</friction>
          <spring_reference>0</spring_reference>
          <spring_stiffness>0</spring_stiffness>
        </dynamics>
        <use_parent_model_frame>1</use_parent_model_frame>
      </axis>
    </joint>
    <link name='Right_Little_Phadist'>
      <pose frame=''>0.000972 -0.043396 0.273584 1.5708 -0.000797 -2.96706</pose>
      <inertial>
        <pose frame=''>0.003 0 0 0 -0 0</pose>
        <mass>0.0137</mass>
        <inertia>
          <ixx>1e-06</ixx>
          <ixy>0</ixy>
          <ixz>0</ixz>
          <iyy>1e-06</iyy>
          <iyz>0</iyz>
          <izz>1e-06</izz>
        </inertia>
      </inertial>
      <collision name='Right_Little_Phadist_collision'>
        <pose frame=''>0 0 0 0 -0 0</pose>
        <geometry>
          <mesh>
            <scale>1 1 1</scale>
            <uri>model://hithand_description/meshes/collision/finger/hit-hand-2-finger-phadist.dae</uri>
          </mesh>
        </geometry>
        <surface>
          <contact>
            <ode/>
          </contact>
          <friction>
            <ode>
              <mu>1</mu>
              <mu2>1</mu2>
            </ode>
          </friction>
        </surface>
      </collision>
      <visual name='Right_Little_Phadist_visual'>
        <pose frame=''>0 0 0 0 -0 0</pose>
        <geometry>
          <mesh>
            <scale>1 1 1</scale>
            <uri>model://hithand_description/meshes/visual/hit-hand-2-finger-phadist.dae</uri>
          </mesh>
        </geometry>
        <material>
          <script>
            <uri>__default__</uri>
            <name>__default__</name>
          </script>
        </material>
      </visual>
      <gravity>1</gravity>
      <velocity_decay/>
      <self_collide>0</self_collide>
    </link>
    <joint name='Right_Little_3' type='revolute'>
      <child>Right_Little_Phadist</child>
      <parent>Right_Little_Phamed</parent>
      <axis>
        <xyz>-0.173652 0.984807 0</xyz>
        <limit>
          <lower>-0.5</lower>
          <upper>1.4</upper>
          <effort>15</effort>
          <velocity>3.14</velocity>
        </limit>
        <dynamics>
          <damping>0.7</damping>
          <friction>0.5</friction>
          <spring_reference>0</spring_reference>
          <spring_stiffness>0</spring_stiffness>
        </dynamics>
        <use_parent_model_frame>1</use_parent_model_frame>
      </axis>
    </joint>
    <link name='Right_Middle_Basecover'>
      <pose frame=''>-0.0037 0.01 0.217784 -3e-06 -1.57079 3.14159</pose>
      <inertial>
        <pose frame=''>0.02749 0 0 0 -0 0</pose>
        <mass>0.0176</mass>
        <inertia>
          <ixx>2e-06</ixx>
          <ixy>0</ixy>
          <ixz>0</ixz>
          <iyy>2e-06</iyy>
          <iyz>0</iyz>
          <izz>2e-06</izz>
        </inertia>
      </inertial>
      <collision name='Right_Middle_Basecover_collision'>
        <pose frame=''>0 0 0 0 -0 0</pose>
        <geometry>
          <cylinder>
            <length>0.001</length>
            <radius>0.001</radius>
          </cylinder>
        </geometry>
        <surface>
          <contact>
            <ode/>
          </contact>
          <friction>
            <ode>
              <mu>1</mu>
              <mu2>1</mu2>
            </ode>
          </friction>
        </surface>
      </collision>
      <visual name='Right_Middle_Basecover_visual'>
        <pose frame=''>0 0 0 0 -0 0</pose>
        <geometry>
          <mesh>
            <scale>1 1 1</scale>
            <uri>model://hithand_description/meshes/visual/hit-hand-2-finger-basecover.dae</uri>
          </mesh>
        </geometry>
        <material>
          <script>
            <uri>__default__</uri>
            <name>__default__</name>
          </script>
        </material>
      </visual>
      <gravity>1</gravity>
      <velocity_decay/>
      <self_collide>0</self_collide>
    </link>
    <joint name='Right_Middle_0' type='revolute'>
      <child>Right_Middle_Basecover</child>
      <parent>base_link_hithand</parent>
      <axis>
        <xyz>1 -0 -0</xyz>
        <limit>
          <lower>-0.261799</lower>
          <upper>0.261799</upper>
          <effort>15</effort>
          <velocity>3.14</velocity>
        </limit>
        <dynamics>
          <damping>0.7</damping>
          <friction>0.5</friction>
          <spring_reference>0</spring_reference>
          <spring_stiffness>0</spring_stiffness>
        </dynamics>
        <use_parent_model_frame>1</use_parent_model_frame>
      </axis>
    </joint>
    <link name='Right_Middle_Phaprox'>
      <pose frame=''>-0.0037 0.01 0.217784 1.5708 -1.57079 3.14159</pose>
      <inertial>
        <pose frame=''>0.02749 0 0 0 -0 0</pose>
        <mass>0.0232</mass>
        <inertia>
          <ixx>2e-06</ixx>
          <ixy>0</ixy>
          <ixz>0</ixz>
          <iyy>2e-06</iyy>
          <iyz>0</iyz>
          <izz>2e-06</izz>
        </inertia>
      </inertial>
      <collision name='Right_Middle_Phaprox_collision'>
        <pose frame=''>0 0 0 0 -0 0</pose>
        <geometry>
          <mesh>
            <scale>1 1 1</scale>
            <uri>model://hithand_description/meshes/collision/finger/hit-hand-2-finger-phaprox.dae</uri>
          </mesh>
        </geometry>
        <surface>
          <contact>
            <ode/>
          </contact>
          <friction>
            <ode>
              <mu>1</mu>
              <mu2>1</mu2>
            </ode>
          </friction>
        </surface>
      </collision>
      <visual name='Right_Middle_Phaprox_visual'>
        <pose frame=''>0 0 0 0 -0 0</pose>
        <geometry>
          <mesh>
            <scale>1 1 1</scale>
            <uri>model://hithand_description/meshes/visual/hit-hand-2-finger-phaprox.dae</uri>
          </mesh>
        </geometry>
        <material>
          <script>
            <uri>__default__</uri>
            <name>__default__</name>
          </script>
        </material>
      </visual>
      <gravity>1</gravity>
      <velocity_decay/>
      <self_collide>0</self_collide>
    </link>
    <joint name='Right_Middle_1' type='revolute'>
      <child>Right_Middle_Phaprox</child>
      <parent>Right_Middle_Basecover</parent>
      <axis>
        <xyz>-3e-06 1 0</xyz>
        <limit>
          <lower>0</lower>
          <upper>1.48353</upper>
          <effort>15</effort>
          <velocity>3.14</velocity>
        </limit>
        <dynamics>
          <damping>0.7</damping>
          <friction>0.5</friction>
          <spring_reference>0</spring_reference>
          <spring_stiffness>0</spring_stiffness>
        </dynamics>
        <use_parent_model_frame>1</use_parent_model_frame>
      </axis>
    </joint>
    <link name='Right_Middle_Phamed'>
      <pose frame=''>-0.0037 0.01 0.272784 1.5708 -1.57079 3.14159</pose>
      <inertial>
        <pose frame=''>0.0025 0 0 0 -0 0</pose>
        <mass>0.0158</mass>
        <inertia>
          <ixx>1e-06</ixx>
          <ixy>0</ixy>
          <ixz>0</ixz>
          <iyy>1e-06</iyy>
          <iyz>0</iyz>
          <izz>1e-06</izz>
        </inertia>
      </inertial>
      <collision name='Right_Middle_Phamed_collision'>
        <pose frame=''>0 0 0 0 -0 0</pose>
        <geometry>
          <mesh>
            <scale>1 1 1</scale>
            <uri>model://hithand_description/meshes/collision/finger/hit-hand-2-finger-phamed.dae</uri>
          </mesh>
        </geometry>
        <surface>
          <contact>
            <ode/>
          </contact>
          <friction>
            <ode>
              <mu>1</mu>
              <mu2>1</mu2>
            </ode>
          </friction>
        </surface>
      </collision>
      <visual name='Right_Middle_Phamed_visual'>
        <pose frame=''>0 0 0 0 -0 0</pose>
        <geometry>
          <mesh>
            <scale>1 1 1</scale>
            <uri>model://hithand_description/meshes/visual/hit-hand-2-finger-phamed.dae</uri>
          </mesh>
        </geometry>
        <material>
          <script>
            <uri>__default__</uri>
            <name>__default__</name>
          </script>
        </material>
      </visual>
      <gravity>1</gravity>
      <velocity_decay/>
      <self_collide>0</self_collide>
    </link>
    <joint name='Right_Middle_2' type='revolute'>
      <child>Right_Middle_Phamed</child>
      <parent>Right_Middle_Phaprox</parent>
      <axis>
        <xyz>-3e-06 1 0</xyz>
        <limit>
          <lower>0</lower>
          <upper>1.13446</upper>
          <effort>15</effort>
          <velocity>3.14</velocity>
        </limit>
        <dynamics>
          <damping>0.7</damping>
          <friction>0.5</friction>
          <spring_reference>0</spring_reference>
          <spring_stiffness>0</spring_stiffness>
        </dynamics>
        <use_parent_model_frame>1</use_parent_model_frame>
      </axis>
    </joint>
    <link name='Right_Middle_Phadist'>
      <pose frame=''>-0.0037 0.01 0.297784 1.5708 -0.000797 -3.14159</pose>
      <inertial>
        <pose frame=''>0.003 0 0 0 -0 0</pose>
        <mass>0.0137</mass>
        <inertia>
          <ixx>1e-06</ixx>
          <ixy>0</ixy>
          <ixz>0</ixz>
          <iyy>1e-06</iyy>
          <iyz>0</iyz>
          <izz>1e-06</izz>
        </inertia>
      </inertial>
      <collision name='Right_Middle_Phadist_collision'>
        <pose frame=''>0 0 0 0 -0 0</pose>
        <geometry>
          <mesh>
            <scale>1 1 1</scale>
            <uri>model://hithand_description/meshes/collision/finger/hit-hand-2-finger-phadist.dae</uri>
          </mesh>
        </geometry>
        <surface>
          <contact>
            <ode/>
          </contact>
          <friction>
            <ode>
              <mu>1</mu>
              <mu2>1</mu2>
            </ode>
          </friction>
        </surface>
      </collision>
      <visual name='Right_Middle_Phadist_visual'>
        <pose frame=''>0 0 0 0 -0 0</pose>
        <geometry>
          <mesh>
            <scale>1 1 1</scale>
            <uri>model://hithand_description/meshes/visual/hit-hand-2-finger-phadist.dae</uri>
          </mesh>
        </geometry>
        <material>
          <script>
            <uri>__default__</uri>
            <name>__default__</name>
          </script>
        </material>
      </visual>
      <gravity>1</gravity>
      <velocity_decay/>
      <self_collide>0</self_collide>
    </link>
    <joint name='Right_Middle_3' type='revolute'>
      <child>Right_Middle_Phadist</child>
      <parent>Right_Middle_Phamed</parent>
      <axis>
        <xyz>-3e-06 1 0</xyz>
        <limit>
          <lower>-0.5</lower>
          <upper>1.4</upper>
          <effort>15</effort>
          <velocity>3.14</velocity>
        </limit>
        <dynamics>
          <damping>0.7</damping>
          <friction>0.5</friction>
          <spring_reference>0</spring_reference>
          <spring_stiffness>0</spring_stiffness>
        </dynamics>
        <use_parent_model_frame>1</use_parent_model_frame>
      </axis>
    </joint>
    <link name='Right_Ring_Basecover'>
      <pose frame=''>0 -0.0168 0.212584 0.087263 -1.57079 -3.14159</pose>
      <inertial>
        <pose frame=''>0.02749 0 0 0 -0 0</pose>
        <mass>0.0176</mass>
        <inertia>
          <ixx>2e-06</ixx>
          <ixy>0</ixy>
          <ixz>0</ixz>
          <iyy>2e-06</iyy>
          <iyz>0</iyz>
          <izz>2e-06</izz>
        </inertia>
      </inertial>
      <collision name='Right_Ring_Basecover_collision'>
        <pose frame=''>0 0 0 0 -0 0</pose>
        <geometry>
          <cylinder>
            <length>0.001</length>
            <radius>0.001</radius>
          </cylinder>
        </geometry>
        <surface>
          <contact>
            <ode/>
          </contact>
          <friction>
            <ode>
              <mu>1</mu>
              <mu2>1</mu2>
            </ode>
          </friction>
        </surface>
      </collision>
      <visual name='Right_Ring_Basecover_visual'>
        <pose frame=''>0 0 0 0 -0 0</pose>
        <geometry>
          <mesh>
            <scale>1 1 1</scale>
            <uri>model://hithand_description/meshes/visual/hit-hand-2-finger-basecover.dae</uri>
          </mesh>
        </geometry>
        <material>
          <script>
            <uri>__default__</uri>
            <name>__default__</name>
          </script>
        </material>
      </visual>
      <gravity>1</gravity>
      <velocity_decay/>
      <self_collide>0</self_collide>
    </link>
    <joint name='Right_Ring_0' type='revolute'>
      <child>Right_Ring_Basecover</child>
      <parent>base_link_hithand</parent>
      <axis>
        <xyz>0.996195 0.087156 -0</xyz>
        <limit>
          <lower>-0.261799</lower>
          <upper>0.261799</upper>
          <effort>15</effort>
          <velocity>3.14</velocity>
        </limit>
        <dynamics>
          <damping>0.7</damping>
          <friction>0.5</friction>
          <spring_reference>0</spring_reference>
          <spring_stiffness>0</spring_stiffness>
        </dynamics>
        <use_parent_model_frame>1</use_parent_model_frame>
      </axis>
    </joint>
    <link name='Right_Ring_Phaprox'>
      <pose frame=''>0 -0.0168 0.212584 1.65806 -1.57079 -3.14159</pose>
      <inertial>
        <pose frame=''>0.02749 0 0 0 -0 0</pose>
        <mass>0.0232</mass>
        <inertia>
          <ixx>2e-06</ixx>
          <ixy>0</ixy>
          <ixz>0</ixz>
          <iyy>2e-06</iyy>
          <iyz>0</iyz>
          <izz>2e-06</izz>
        </inertia>
      </inertial>
      <collision name='Right_Ring_Phaprox_collision'>
        <pose frame=''>0 0 0 0 -0 0</pose>
        <geometry>
          <mesh>
            <scale>1 1 1</scale>
            <uri>model://hithand_description/meshes/collision/finger/hit-hand-2-finger-phaprox.dae</uri>
          </mesh>
        </geometry>
        <surface>
          <contact>
            <ode/>
          </contact>
          <friction>
            <ode>
              <mu>1</mu>
              <mu2>1</mu2>
            </ode>
          </friction>
        </surface>
      </collision>
      <visual name='Right_Ring_Phaprox_visual'>
        <pose frame=''>0 0 0 0 -0 0</pose>
        <geometry>
          <mesh>
            <scale>1 1 1</scale>
            <uri>model://hithand_description/meshes/visual/hit-hand-2-finger-phaprox.dae</uri>
          </mesh>
        </geometry>
        <material>
          <script>
            <uri>__default__</uri>
            <name>__default__</name>
          </script>
        </material>
      </visual>
      <gravity>1</gravity>
      <velocity_decay/>
      <self_collide>0</self_collide>
    </link>
    <joint name='Right_Ring_1' type='revolute'>
      <child>Right_Ring_Phaprox</child>
      <parent>Right_Ring_Basecover</parent>
      <axis>
        <xyz>-0.08716 0.996194 0</xyz>
        <limit>
          <lower>0</lower>
          <upper>1.48353</upper>
          <effort>15</effort>
          <velocity>3.14</velocity>
        </limit>
        <dynamics>
          <damping>0.7</damping>
          <friction>0.5</friction>
          <spring_reference>0</spring_reference>
          <spring_stiffness>0</spring_stiffness>
        </dynamics>
        <use_parent_model_frame>1</use_parent_model_frame>
      </axis>
    </joint>
    <link name='Right_Ring_Phamed'>
      <pose frame=''>0 -0.0168 0.267584 1.65806 -1.57079 -3.14159</pose>
      <inertial>
        <pose frame=''>0.0025 0 0 0 -0 0</pose>
        <mass>0.0158</mass>
        <inertia>
          <ixx>1e-06</ixx>
          <ixy>0</ixy>
          <ixz>0</ixz>
          <iyy>1e-06</iyy>
          <iyz>0</iyz>
          <izz>1e-06</izz>
        </inertia>
      </inertial>
      <collision name='Right_Ring_Phamed_collision'>
        <pose frame=''>0 0 0 0 -0 0</pose>
        <geometry>
          <mesh>
            <scale>1 1 1</scale>
            <uri>model://hithand_description/meshes/collision/finger/hit-hand-2-finger-phamed.dae</uri>
          </mesh>
        </geometry>
        <surface>
          <contact>
            <ode/>
          </contact>
          <friction>
            <ode>
              <mu>1</mu>
              <mu2>1</mu2>
            </ode>
          </friction>
        </surface>
      </collision>
      <visual name='Right_Ring_Phamed_visual'>
        <pose frame=''>0 0 0 0 -0 0</pose>
        <geometry>
          <mesh>
            <scale>1 1 1</scale>
            <uri>model://hithand_description/meshes/visual/hit-hand-2-finger-phamed.dae</uri>
          </mesh>
        </geometry>
        <material>
          <script>
            <uri>__default__</uri>
            <name>__default__</name>
          </script>
        </material>
      </visual>
      <gravity>1</gravity>
      <velocity_decay/>
      <self_collide>0</self_collide>
    </link>
    <joint name='Right_Ring_2' type='revolute'>
      <child>Right_Ring_Phamed</child>
      <parent>Right_Ring_Phaprox</parent>
      <axis>
        <xyz>-0.08716 0.996194 0</xyz>
        <limit>
          <lower>0</lower>
          <upper>1.13446</upper>
          <effort>15</effort>
          <velocity>3.14</velocity>
        </limit>
        <dynamics>
          <damping>0.7</damping>
          <friction>0.5</friction>
          <spring_reference>0</spring_reference>
          <spring_stiffness>0</spring_stiffness>
        </dynamics>
        <use_parent_model_frame>1</use_parent_model_frame>
      </axis>
    </joint>
    <link name='Right_Ring_Phadist'>
      <pose frame=''>0 -0.0168 0.292584 1.5708 -0.000797 -3.05432</pose>
      <inertial>
        <pose frame=''>0.003 0 0 0 -0 0</pose>
        <mass>0.0137</mass>
        <inertia>
          <ixx>1e-06</ixx>
          <ixy>0</ixy>
          <ixz>0</ixz>
          <iyy>1e-06</iyy>
          <iyz>0</iyz>
          <izz>1e-06</izz>
        </inertia>
      </inertial>
      <collision name='Right_Ring_Phadist_collision'>
        <pose frame=''>0 0 0 0 -0 0</pose>
        <geometry>
          <mesh>
            <scale>1 1 1</scale>
            <uri>model://hithand_description/meshes/collision/finger/hit-hand-2-finger-phadist.dae</uri>
          </mesh>
        </geometry>
        <surface>
          <contact>
            <ode/>
          </contact>
          <friction>
            <ode>
              <mu>1</mu>
              <mu2>1</mu2>
            </ode>
          </friction>
        </surface>
      </collision>
      <visual name='Right_Ring_Phadist_visual'>
        <pose frame=''>0 0 0 0 -0 0</pose>
        <geometry>
          <mesh>
            <scale>1 1 1</scale>
            <uri>model://hithand_description/meshes/visual/hit-hand-2-finger-phadist.dae</uri>
          </mesh>
        </geometry>
        <material>
          <script>
            <uri>__default__</uri>
            <name>__default__</name>
          </script>
        </material>
      </visual>
      <gravity>1</gravity>
      <velocity_decay/>
      <self_collide>0</self_collide>
    </link>
    <joint name='Right_Ring_3' type='revolute'>
      <child>Right_Ring_Phadist</child>
      <parent>Right_Ring_Phamed</parent>
      <axis>
        <xyz>-0.08716 0.996194 0</xyz>
        <limit>
          <lower>-0.5</lower>
          <upper>1.4</upper>
          <effort>15</effort>
          <velocity>3.14</velocity>
        </limit>
        <dynamics>
          <damping>0.7</damping>
          <friction>0.5</friction>
          <spring_reference>0</spring_reference>
          <spring_stiffness>0</spring_stiffness>
        </dynamics>
        <use_parent_model_frame>1</use_parent_model_frame>
      </axis>
    </joint>
    <link name='Right_Thumb_Basecover'>
      <pose frame=''>0.062176 0.044373 0.178735 0.22581 -1.08366 0.411355</pose>
      <inertial>
        <pose frame=''>0.02749 0 0 0 -0 0</pose>
        <mass>0.0176</mass>
        <inertia>
          <ixx>2e-06</ixx>
          <ixy>0</ixy>
          <ixz>0</ixz>
          <iyy>2e-06</iyy>
          <iyz>0</iyz>
          <izz>2e-06</izz>
        </inertia>
      </inertial>
      <collision name='Right_Thumb_Basecover_collision'>
        <pose frame=''>0 0 0 0 -0 0</pose>
        <geometry>
          <cylinder>
            <length>0.001</length>
            <radius>0.001</radius>
          </cylinder>
        </geometry>
        <surface>
          <contact>
            <ode/>
          </contact>
          <friction>
            <ode>
              <mu>1</mu>
              <mu2>1</mu2>
            </ode>
          </friction>
        </surface>
      </collision>
      <visual name='Right_Thumb_Basecover_visual'>
        <pose frame=''>0 0 0 0 -0 0</pose>
        <geometry>
          <mesh>
            <scale>1 1 1</scale>
            <uri>model://hithand_description/meshes/visual/hit-hand-2-finger-basecover.dae</uri>
          </mesh>
        </geometry>
        <material>
          <script>
            <uri>__default__</uri>
            <name>__default__</name>
          </script>
        </material>
      </visual>
      <gravity>1</gravity>
      <velocity_decay/>
      <self_collide>0</self_collide>
    </link>
    <joint name='Right_Thumb_0' type='revolute'>
      <child>Right_Thumb_Basecover</child>
      <parent>base_link_hithand</parent>
      <axis>
        <xyz>-0.699871 -0.549587 0.456217</xyz>
        <limit>
          <lower>-0.261799</lower>
          <upper>0.261799</upper>
          <effort>15</effort>
          <velocity>3.14</velocity>
        </limit>
        <dynamics>
          <damping>0.7</damping>
          <friction>0.5</friction>
          <spring_reference>0</spring_reference>
          <spring_stiffness>0</spring_stiffness>
        </dynamics>
        <use_parent_model_frame>1</use_parent_model_frame>
      </axis>
    </joint>
    <link name='Right_Thumb_Phaprox'>
      <pose frame=''>0.062176 0.044373 0.178735 1.79661 -1.08366 0.411355</pose>
      <inertial>
        <pose frame=''>0.02749 0 0 0 -0 0</pose>
        <mass>0.0232</mass>
        <inertia>
          <ixx>2e-06</ixx>
          <ixy>0</ixy>
          <ixz>0</ixz>
          <iyy>2e-06</iyy>
          <iyz>0</iyz>
          <izz>2e-06</izz>
        </inertia>
      </inertial>
      <collision name='Right_Thumb_Phaprox_collision'>
        <pose frame=''>0 0 0 0 -0 0</pose>
        <geometry>
          <mesh>
            <scale>1 1 1</scale>
            <uri>model://hithand_description/meshes/collision/finger/hit-hand-2-finger-phaprox.dae</uri>
          </mesh>
        </geometry>
        <surface>
          <contact>
            <ode/>
          </contact>
          <friction>
            <ode>
              <mu>1</mu>
              <mu2>1</mu2>
            </ode>
          </friction>
        </surface>
      </collision>
      <visual name='Right_Thumb_Phaprox_visual'>
        <pose frame=''>0 0 0 0 -0 0</pose>
        <geometry>
          <mesh>
            <scale>1 1 1</scale>
            <uri>model://hithand_description/meshes/visual/hit-hand-2-finger-phaprox.dae</uri>
          </mesh>
        </geometry>
        <material>
          <script>
            <uri>__default__</uri>
            <name>__default__</name>
          </script>
        </material>
      </visual>
      <gravity>1</gravity>
      <velocity_decay/>
      <self_collide>0</self_collide>
    </link>
    <joint name='Right_Thumb_1' type='revolute'>
      <child>Right_Thumb_Phaprox</child>
      <parent>Right_Thumb_Basecover</parent>
      <axis>
        <xyz>0.57105 -0.814198 -0.104808</xyz>
        <limit>
          <lower>0</lower>
          <upper>1.48353</upper>
          <effort>15</effort>
          <velocity>3.14</velocity>
        </limit>
        <dynamics>
          <damping>0.7</damping>
          <friction>0.5</friction>
          <spring_reference>0</spring_reference>
          <spring_stiffness>0</spring_stiffness>
        </dynamics>
        <use_parent_model_frame>1</use_parent_model_frame>
      </axis>
    </joint>
    <link name='Right_Thumb_Phamed'>
      <pose frame=''>0.085774 0.054667 0.227337 1.79661 -1.08366 0.411355</pose>
      <inertial>
        <pose frame=''>0.0025 0 0 0 -0 0</pose>
        <mass>0.0158</mass>
        <inertia>
          <ixx>1e-06</ixx>
          <ixy>0</ixy>
          <ixz>0</ixz>
          <iyy>1e-06</iyy>
          <iyz>0</iyz>
          <izz>1e-06</izz>
        </inertia>
      </inertial>
      <collision name='Right_Thumb_Phamed_collision'>
        <pose frame=''>0 0 0 0 -0 0</pose>
        <geometry>
          <mesh>
            <scale>1 1 1</scale>
            <uri>model://hithand_description/meshes/collision/finger/hit-hand-2-finger-phamed.dae</uri>
          </mesh>
        </geometry>
        <surface>
          <contact>
            <ode/>
          </contact>
          <friction>
            <ode>
              <mu>1</mu>
              <mu2>1</mu2>
            </ode>
          </friction>
        </surface>
      </collision>
      <visual name='Right_Thumb_Phamed_visual'>
        <pose frame=''>0 0 0 0 -0 0</pose>
        <geometry>
          <mesh>
            <scale>1 1 1</scale>
            <uri>model://hithand_description/meshes/visual/hit-hand-2-finger-phamed.dae</uri>
          </mesh>
        </geometry>
        <material>
          <script>
            <uri>__default__</uri>
            <name>__default__</name>
          </script>
        </material>
      </visual>
      <gravity>1</gravity>
      <velocity_decay/>
      <self_collide>0</self_collide>
    </link>
    <joint name='Right_Thumb_2' type='revolute'>
      <child>Right_Thumb_Phamed</child>
      <parent>Right_Thumb_Phaprox</parent>
      <axis>
        <xyz>0.57105 -0.814198 -0.104808</xyz>
        <limit>
          <lower>0</lower>
          <upper>1.13446</upper>
          <effort>15</effort>
          <velocity>3.14</velocity>
        </limit>
        <dynamics>
          <damping>0.7</damping>
          <friction>0.5</friction>
          <spring_reference>0</spring_reference>
          <spring_stiffness>0</spring_stiffness>
        </dynamics>
        <use_parent_model_frame>1</use_parent_model_frame>
      </axis>
    </joint>
    <link name='Right_Thumb_Phadist'>
      <pose frame=''>0.0965 0.059347 0.249429 1.6888 0.472948 0.665593</pose>
      <inertial>
        <pose frame=''>0.003 0 0 0 -0 0</pose>
        <mass>0.0137</mass>
        <inertia>
          <ixx>1e-06</ixx>
          <ixy>0</ixy>
          <ixz>0</ixz>
          <iyy>1e-06</iyy>
          <iyz>0</iyz>
          <izz>1e-06</izz>
        </inertia>
      </inertial>
      <collision name='Right_Thumb_Phadist_collision'>
        <pose frame=''>0 0 0 0 -0 0</pose>
        <geometry>
          <mesh>
            <scale>1 1 1</scale>
            <uri>model://hithand_description/meshes/collision/finger/hit-hand-2-finger-phadist.dae</uri>
          </mesh>
        </geometry>
        <surface>
          <contact>
            <ode/>
          </contact>
          <friction>
            <ode>
              <mu>1</mu>
              <mu2>1</mu2>
            </ode>
          </friction>
        </surface>
      </collision>
      <visual name='Right_Thumb_Phadist_visual'>
        <pose frame=''>0 0 0 0 -0 0</pose>
        <geometry>
          <mesh>
            <scale>1 1 1</scale>
            <uri>model://hithand_description/meshes/visual/hit-hand-2-finger-phadist.dae</uri>
          </mesh>
        </geometry>
        <material>
          <script>
            <uri>__default__</uri>
            <name>__default__</name>
          </script>
        </material>
      </visual>
      <gravity>1</gravity>
      <velocity_decay/>
      <self_collide>0</self_collide>
    </link>
    <joint name='Right_Thumb_3' type='revolute'>
      <child>Right_Thumb_Phadist</child>
      <parent>Right_Thumb_Phamed</parent>
      <axis>
        <xyz>0.57105 -0.814198 -0.104808</xyz>
        <limit>
          <lower>-0.5</lower>
          <upper>1.4</upper>
          <effort>15</effort>
          <velocity>3.14</velocity>
        </limit>
        <dynamics>
          <damping>0.7</damping>
          <friction>0.5</friction>
          <spring_reference>0</spring_reference>
          <spring_stiffness>0</spring_stiffness>
        </dynamics>
        <use_parent_model_frame>1</use_parent_model_frame>
      </axis>
    </joint>
  </model>
</sdf>
