<?xml version="1.0"?>
<robot xmlns:xacro="http://www.ros.org/wiki/xacro" name="hithand">
    <xacro:include filename="$(find hithand_description)/urdf/transmission.xacro" />
    <xacro:include filename="$(find hithand_description)/urdf/hithand.gazebo" />
    <xacro:property name="mu1" value="0.6"/>
    <xacro:property name="mu2" value="0.6"/>
    <link name="world"/>
    <joint name="fixed" type="fixed">
        <parent link="world"/>
        <child link="base_link"/>
    </joint>
    <link name="base_link">
  	<inertial>
      		<origin xyz="0.0 0.0 0.0"
        		rpy="0 0 0" />
      		<mass value="1.0"/>
      		<inertia ixx="1.0" ixy="0.0" ixz="0.0" iyy="1.0" iyz="0.0" izz="1.0" />
    	</inertial>
   	<visual>
      		<origin rpy="0 0 0" xyz="0 0 0" />
      		<geometry>
        		<mesh filename="package://hithand_description/meshes/visual/hit-hand-2-palm-right.dae"/>
      		</geometry>
      		<material name="grey" />
    	</visual>
    	<collision>
      		<origin rpy="0 0 0" xyz="0 0 0" />
      		<geometry name="hithand_right_palm_collision">
        		<cylinder length="0.001" radius="0.001" />
      		</geometry>
    	</collision>
  </link>



    <xacro:macro name="finger" params="prefix *transform_palm2finger">
        <!-- #########################fINGER######################## -->
        <link name="Right_${prefix}_Basecover">
            <inertial>
                <origin xyz="0 0 0"
                    rpy="0 0 0" />
                <mass value="1.0" />
                <inertia ixx="1.0" ixy="0.0" ixz="0.0" iyy="1.0" iyz="0.0" izz="1.0" />
            </inertial>
            <visual>
                <origin xyz="0 0 0"
                    rpy="0 0 0" />
                <geometry>
                <!-- <mesh filename="file://$(arg meshDirectory)visual/hit-hand-2-finger-basecover.dae" /> -->
                <mesh filename="package://hithand_description/meshes/visual/hit-hand-2-finger-basecover.dae"/>
                </geometry>
            <material name="white"/>
            </visual>
            <collision>
                <origin xyz="0 0 0"
                    rpy="0 0 0" />
                <geometry name='hithand_${prefix}_base_cover'>
                    <cylinder length="0.001" radius="0.001" />
                </geometry>
                <surface>
                  <friction>
                    <ode>
                      <mu>${mu1}</mu>
                      <mu2>${mu2}</mu2>
                    </ode>
                  </friction>
                </surface>
            </collision>
      </link>

      <joint name="Right_${prefix}_1"
        type="revolute">
            <!-- joint origin in parent link frame -->
            <xacro:insert_block name="transform_palm2finger" />
            <parent link="base_link" />
            <child link="Right_${prefix}_Basecover" />
        <axis xyz="0 0 1" />
        <limit effort="30" lower="-0.50" upper="1.4" velocity="3.14"/>
      </joint>

      <link name="Right_${prefix}_Phoaprox">
            <inertial>
                    <origin xyz="0.06217593 0.044372912 0.078734808"
                            rpy="0.225810 -1.083656 0.411355" />
                    <mass value="1.0" />
                    <inertia ixx="1.0" ixy="0.0" ixz="0.0" iyy="1.0" iyz="0.0" izz="1.0" />
            </inertial>
            <visual>
                    <origin xyz="0 0 0"
                            rpy="0 0 0" />
                    <geometry>
                            <mesh filename="package://hithand_description/meshes/visual/hit-hand-2-finger-phaprox.dae" />
                    </geometry>
            <material name="lightblue"/>
            </visual>
            <collision>
                    <origin xyz="0.03 0 0"
                            rpy="0 0 0" />
                    <geometry name='hithand_${prefix}_phoarpox'>
                            <box size="0.03 0.03 0.02" />
                    </geometry>
                    <surface>
                      <friction>
                        <ode>
                          <mu>${mu1}</mu>
                          <mu2>${mu2}</mu2>
                        </ode>
                      </friction>
                    </surface>
            </collision>
      </link>

      <joint name="Right_${prefix}_2"
        type="revolute">
            <origin xyz="0 0 0 "
                    rpy="1.5708 0 0" />
            <parent link="Right_${prefix}_Basecover" />
            <child link="Right_${prefix}_Phoaprox" />
            <axis xyz="0 0 1" />
            <limit effort="30" lower="-0.50" upper="1.4" velocity="3.14"/>
      </joint>

      <link name="Right_${prefix}_Phamed">
            <inertial>
                    <origin xyz="0 0 0"
                            rpy="0 0 0" />
                    <mass value="1.0" />
                    <inertia ixx="1.0" ixy="0.0" ixz="0.0" iyy="1.0" iyz="0.0" izz="1.0" />
            </inertial>
            <visual>
                    <origin xyz="0 0 0"
                            rpy="0 0 0" />
                    <geometry>
                <mesh filename="package://hithand_description/meshes/visual/hit-hand-2-finger-phamed.dae" />
                    </geometry>
            <material name="white"/>
            </visual>
            <collision>
                    <origin xyz="0.01 0 0"
                            rpy="0 0 0" />
                    <geometry name='hithand_${prefix}_phamed'>
                            <box size="0.01 0.02 0.02" />
            </geometry>
            <surface>
              <friction>
                <ode>
                  <mu>${mu1}</mu>
                  <mu2>${mu2}</mu2>
                </ode>
              </friction>
            </surface>
            </collision>
      </link>

      <joint name="Right_${prefix}_3"
        type="revolute">
            <origin xyz="0.055 0 0"
                    rpy="0 0 0" />
            <parent link="Right_${prefix}_Phoaprox" />
            <child link="Right_${prefix}_Phamed" />
            <axis xyz="0 0 1" />
            <limit effort="30" lower="-0.50" upper="1.4" velocity="3.14"/>
      </joint>

      <link name="Right_${prefix}_Phadist">
            <inertial>
                    <origin xyz="0 0 0"
                            rpy="0 0 0" />
                    <mass value="1.0" />
                    <inertia ixx="1.0" ixy="0.0" ixz="0.0" iyy="1.0" iyz="0.0" izz="1.0" />
            </inertial>
            <visual>
                    <origin xyz="0 0 0"
                            rpy="0 0 0" />
                    <geometry>
                            <mesh filename="package://hithand_description/meshes/visual/hit-hand-2-finger-phadist.dae" />
                    </geometry>
                    <material name="lightblue"/>
            </visual>
            <collision>
                    <origin xyz="0 0 0"
                            rpy="0 0 0" />
                    <geometry name='hithand_${prefix}_phadist'>
                            <mesh filename="package://hithand_description/meshes/visual/hit-hand-2-finger-phadist.dae" />
                    </geometry>
                    <surface>
                      <friction>
                        <ode>
                          <mu>${mu1}</mu>
                          <mu2>${mu2}</mu2>
                        </ode>
                      </friction>
                    </surface>
            </collision>
      </link>

      <joint name="Right_${prefix}_4"
        type="revolute">
            <origin xyz="0.025 0 0"
                    rpy="0 0 -1.57" />
            <parent link="Right_${prefix}_Phamed" />
            <child link="Right_${prefix}_Phadist" />
            <axis xyz="0 0 1" />
            <limit effort="30" lower="-0.50" upper="1.4" velocity="3.14"/>
      </joint>
    </xacro:macro>

+
    <xacro:finger prefix="Thumb"  >
            <origin xyz="0.06217593 0.044372912 0.078734808"
            rpy="0.225810 -1.083656 0.411355" />
    </xacro:finger>

    <xacro:finger prefix="Index"  >
        <origin xyz="-0.002529881 0.03680013 0.107783545"
      		rpy="3.054326 -1.570796 0.000000" />
    </xacro:finger>


    <xacro:finger prefix="Middle"  >
            <origin xyz="-0.0037 0.01  0.117783545"
      		rpy="-3.141593 -1.570796 0.000000" />
    </xacro:finger>
    <xacro:finger prefix="Ring"   >
            <origin xyz="0 -0.01680013 0.11258354"
            rpy="-3.054326 -1.570796 0.000000" />
    </xacro:finger>
    <xacro:finger prefix="Little"  >
            <origin xyz="0.000971571 -0.0433963 0.093583545"
            rpy="-2.967060 -1.570796 0.000000" />
    </xacro:finger>


</robot>