<sdf version='1.6'>
  <model name='hithand'>
    <link name='base_link'>
      <pose frame=''>0 0 0 0 -0 0</pose>
      <inertial>
        <pose frame=''>0 0 0 0 -0 0</pose>
        <mass>1</mass>
        <inertia>
          <ixx>1</ixx>
          <ixy>0</ixy>
          <ixz>0</ixz>
          <iyy>1</iyy>
          <iyz>0</iyz>
          <izz>1</izz>
        </inertia>
      </inertial>
      <collision name='base_link_collision'>
        <pose frame=''>0 0 0 0 -0 0</pose>
        <geometry>
          <cylinder>
            <length>0.001</length>
            <radius>0.001</radius>
          </cylinder>
        </geometry>
        <surface>
          <contact>
            <ode/>
          </contact>
          <friction>
            <ode/>
          </friction>
        </surface>
      </collision>
      <visual name='base_link_visual'>
        <pose frame=''>0 0 0 0 -0 0</pose>
        <geometry>
          <mesh>
            <scale>1 1 1</scale>
            <uri>model://hithand_description/meshes/visual/hit-hand-2-palm-right.dae</uri>
          </mesh>
        </geometry>
        <material>
          <script>
            <uri>__default__</uri>
            <name>__default__</name>
          </script>
        </material>
      </visual>
      <gravity>0</gravity>
      <velocity_decay/>
      <self_collide>1</self_collide>
    </link>
    <joint name='fixed' type='fixed'>
      <child>base_link</child>
      <parent>world</parent>
    </joint>
    <link name='Right_Thumb_Basecover'>
      <pose frame=''>0.062176 0.044373 0.078735 0.22581 -1.08366 0.411355</pose>
      <inertial>
        <pose frame=''>0 0 0 0 -0 0</pose>
        <mass>1</mass>
        <inertia>
          <ixx>1</ixx>
          <ixy>0</ixy>
          <ixz>0</ixz>
          <iyy>1</iyy>
          <iyz>0</iyz>
          <izz>1</izz>
        </inertia>
      </inertial>
      <collision name='Right_Thumb_Basecover_collision'>
        <pose frame=''>0 0 0 0 -0 0</pose>
        <geometry>
          <cylinder>
            <length>0.001</length>
            <radius>0.001</radius>
          </cylinder>
        </geometry>
        <surface>
          <contact>
            <ode/>
          </contact>
          <friction>
            <ode>
              <mu>0.2</mu>
              <mu2>0.2</mu2>
            </ode>
          </friction>
        </surface>
      </collision>
      <visual name='Right_Thumb_Basecover_visual'>
        <pose frame=''>0 0 0 0 -0 0</pose>
        <geometry>
          <mesh>
            <scale>1 1 1</scale>
            <uri>model://hithand_description/meshes/visual/hit-hand-2-finger-basecover.dae</uri>
          </mesh>
        </geometry>
        <material>
          <script>
            <uri>__default__</uri>
            <name>__default__</name>
          </script>
        </material>
      </visual>
      <gravity>0</gravity>
      <velocity_decay/>
      <self_collide>1</self_collide>
    </link>
    <joint name='Right_Thumb_1' type='revolute'>
      <child>Right_Thumb_Basecover</child>
      <parent>base_link</parent>
      <axis>
        <xyz>-0.699871 -0.549587 0.456217</xyz>
        <limit>
          <lower>-0.5</lower>
          <upper>1.4</upper>
          <effort>1000</effort>
          <velocity>3.14</velocity>
        </limit>
        <dynamics>
          <damping>0.7</damping>
          <friction>0.5</friction>
          <spring_reference>0</spring_reference>
          <spring_stiffness>0</spring_stiffness>
        </dynamics>
        <use_parent_model_frame>1</use_parent_model_frame>
      </axis>
    </joint>
    <link name='Right_Thumb_Phoaprox'>
      <pose frame=''>0.062176 0.044373 0.078735 1.79661 -1.08366 0.411355</pose>
      <inertial>
        <pose frame=''>0.062176 0.044373 0.078735 0.22581 -1.08366 0.411355</pose>
        <mass>1</mass>
        <inertia>
          <ixx>1</ixx>
          <ixy>0</ixy>
          <ixz>0</ixz>
          <iyy>1</iyy>
          <iyz>0</iyz>
          <izz>1</izz>
        </inertia>
      </inertial>
      <collision name='Right_Thumb_Phoaprox_collision'>
        <pose frame=''>0.03 0 0 0 -0 0</pose>
        <geometry>
          <box>
            <size>0.03 0.03 0.02</size>
          </box>
        </geometry>
        <surface>
          <contact>
            <ode/>
          </contact>
          <friction>
            <ode/>
          </friction>
        </surface>
      </collision>
      <visual name='Right_Thumb_Phoaprox_visual'>
        <pose frame=''>0 0 0 0 -0 0</pose>
        <geometry>
          <mesh>
            <scale>1 1 1</scale>
            <uri>model://hithand_description/meshes/visual/hit-hand-2-finger-phaprox.dae</uri>
          </mesh>
        </geometry>
        <material>
          <script>
            <uri>__default__</uri>
            <name>__default__</name>
          </script>
        </material>
      </visual>
      <gravity>0</gravity>
      <velocity_decay/>
      <self_collide>1</self_collide>
    </link>
    <joint name='Right_Thumb_2' type='revolute'>
      <child>Right_Thumb_Phoaprox</child>
      <parent>Right_Thumb_Basecover</parent>
      <axis>
        <xyz>0.57105 -0.814198 -0.104808</xyz>
        <limit>
          <lower>-0.5</lower>
          <upper>1.4</upper>
          <effort>1000</effort>
          <velocity>3.14</velocity>
        </limit>
        <dynamics>
          <damping>0.7</damping>
          <friction>0.5</friction>
          <spring_reference>0</spring_reference>
          <spring_stiffness>0</spring_stiffness>
        </dynamics>
        <use_parent_model_frame>1</use_parent_model_frame>
      </axis>
    </joint>
    <link name='Right_Thumb_Phamed'>
      <pose frame=''>0.085774 0.054667 0.127337 1.79661 -1.08366 0.411355</pose>
      <inertial>
        <pose frame=''>0 0 0 0 -0 0</pose>
        <mass>1</mass>
        <inertia>
          <ixx>1</ixx>
          <ixy>0</ixy>
          <ixz>0</ixz>
          <iyy>1</iyy>
          <iyz>0</iyz>
          <izz>1</izz>
        </inertia>
      </inertial>
      <collision name='Right_Thumb_Phamed_collision'>
        <pose frame=''>0.01 0 0 0 -0 0</pose>
        <geometry>
          <box>
            <size>0.01 0.02 0.02</size>
          </box>
        </geometry>
        <surface>
          <contact>
            <ode/>
          </contact>
          <friction>
            <ode/>
          </friction>
        </surface>
      </collision>
      <visual name='Right_Thumb_Phamed_visual'>
        <pose frame=''>0 0 0 0 -0 0</pose>
        <geometry>
          <mesh>
            <scale>1 1 1</scale>
            <uri>model://hithand_description/meshes/visual/hit-hand-2-finger-phamed.dae</uri>
          </mesh>
        </geometry>
        <material>
          <script>
            <uri>__default__</uri>
            <name>__default__</name>
          </script>
        </material>
      </visual>
      <gravity>0</gravity>
      <velocity_decay/>
      <self_collide>1</self_collide>
    </link>
    <joint name='Right_Thumb_3' type='revolute'>
      <child>Right_Thumb_Phamed</child>
      <parent>Right_Thumb_Phoaprox</parent>
      <axis>
        <xyz>0.57105 -0.814198 -0.104808</xyz>
        <limit>
          <lower>-0.5</lower>
          <upper>1.4</upper>
          <effort>1000</effort>
          <velocity>3.14</velocity>
        </limit>
        <dynamics>
          <damping>0.7</damping>
          <friction>0.5</friction>
          <spring_reference>0</spring_reference>
          <spring_stiffness>0</spring_stiffness>
        </dynamics>
        <use_parent_model_frame>1</use_parent_model_frame>
      </axis>
    </joint>
    <link name='Right_Thumb_Phadist'>
      <pose frame=''>0.0965 0.059347 0.149429 1.6888 0.472948 0.665593</pose>
      <inertial>
        <pose frame=''>0 0 0 0 -0 0</pose>
        <mass>1</mass>
        <inertia>
          <ixx>1</ixx>
          <ixy>0</ixy>
          <ixz>0</ixz>
          <iyy>1</iyy>
          <iyz>0</iyz>
          <izz>1</izz>
        </inertia>
      </inertial>
      <collision name='Right_Thumb_Phadist_collision'>
        <pose frame=''>0 0 0 0 -0 0</pose>
        <geometry>
          <mesh>
            <scale>1 1 1</scale>
            <uri>model://hithand_description/meshes/visual/hit-hand-2-finger-phadist.dae</uri>
          </mesh>
        </geometry>
        <surface>
          <contact>
            <ode/>
          </contact>
          <friction>
            <ode/>
          </friction>
        </surface>
      </collision>
      <visual name='Right_Thumb_Phadist_visual'>
        <pose frame=''>0 0 0 0 -0 0</pose>
        <geometry>
          <mesh>
            <scale>1 1 1</scale>
            <uri>model://hithand_description/meshes/visual/hit-hand-2-finger-phadist.dae</uri>
          </mesh>
        </geometry>
        <material>
          <script>
            <uri>__default__</uri>
            <name>__default__</name>
          </script>
        </material>
      </visual>
      <gravity>0</gravity>
      <velocity_decay/>
      <self_collide>1</self_collide>
    </link>
    <joint name='Right_Thumb_4' type='revolute'>
      <child>Right_Thumb_Phadist</child>
      <parent>Right_Thumb_Phamed</parent>
      <axis>
        <xyz>0.57105 -0.814198 -0.104808</xyz>
        <limit>
          <lower>-0.5</lower>
          <upper>1.4</upper>
          <effort>1000</effort>
          <velocity>3.14</velocity>
        </limit>
        <dynamics>
          <damping>0.7</damping>
          <friction>0.5</friction>
          <spring_reference>0</spring_reference>
          <spring_stiffness>0</spring_stiffness>
        </dynamics>
        <use_parent_model_frame>1</use_parent_model_frame>
      </axis>
    </joint>
    <plugin name='gazebo_ros_control' filename='libgazebo_ros_control.so'>
      <robotNamespace>/hithand</robotNamespace>
      <robotSimType>gazebo_ros_control/DefaultRobotHWSim</robotSimType>
    </plugin>
    <static>0</static>
  </model>
</sdf>
