<?xml version="1.0" encoding="utf-8"?>
<!-- =================================================================================== -->
<!-- |    This document was autogenerated by xacro from hithand.xacro                  | -->
<!-- |    EDITING THIS FILE BY HAND IS NOT RECOMMENDED                                 | -->
<!-- =================================================================================== -->
<robot name="hithand">
  <!--PositionJointInterface  EffortJointInterface-->
  <transmission name="tran_Thumb_1">
    <type>transmission_interface/SimpleTransmission</type>
    <joint name="Right_Thumb_1">
      <hardwareInterface>hardware_interface/PositionJointInterface</hardwareInterface>
    </joint>
    <actuator name="motor_Thumb_1">
      <hardwareInterface>hardware_interface/PositionJointInterface</hardwareInterface>
      <mechanicalReduction>1</mechanicalReduction>
    </actuator>
  </transmission>
  <transmission name="tran_Thumb_2">
    <type>transmission_interface/SimpleTransmission</type>
    <joint name="Right_Thumb_2">
      <hardwareInterface>hardware_interface/PositionJointInterface</hardwareInterface>
    </joint>
    <actuator name="motor_Thumb_2">
      <hardwareInterface>hardware_interface/PositionJointInterface</hardwareInterface>
      <mechanicalReduction>1</mechanicalReduction>
    </actuator>
  </transmission>
  <transmission name="tran_Thumb_3">
    <type>transmission_interface/SimpleTransmission</type>
    <joint name="Right_Thumb_3">
      <hardwareInterface>hardware_interface/PositionJointInterface</hardwareInterface>
    </joint>
    <actuator name="motor_Thumb_3">
      <hardwareInterface>hardware_interface/PositionJointInterface</hardwareInterface>
      <mechanicalReduction>1</mechanicalReduction>
    </actuator>
  </transmission>
  <transmission name="tran_Thumb_4">
    <type>transmission_interface/SimpleTransmission</type>
    <joint name="Right_Thumb_4">
      <hardwareInterface>hardware_interface/PositionJointInterface</hardwareInterface>
    </joint>
    <actuator name="motor_Thumb_4">
      <hardwareInterface>hardware_interface/PositionJointInterface</hardwareInterface>
      <mechanicalReduction>1</mechanicalReduction>
    </actuator>
  </transmission>
  <!--    <xacro:hithand_transmission finger_name="Index">-->
  <!--    </xacro:hithand_transmission>-->
  <!--    <xacro:hithand_transmission finger_name="Middle">-->
  <!--    </xacro:hithand_transmission>-->
  <!--    <xacro:hithand_transmission finger_name="Ring">-->
  <!--    </xacro:hithand_transmission>-->
  <!--    <xacro:hithand_transmission finger_name="Little">-->
  <!--    </xacro:hithand_transmission>-->
  <gazebo>
    <plugin filename="libgazebo_ros_control.so" name="gazebo_ros_control">
      <robotNamespace>/hithand</robotNamespace>
      <robotSimType>gazebo_ros_control/DefaultRobotHWSim</robotSimType>
    </plugin>
  </gazebo>
  <!--set static works only if no reference is specified -->
  <gazebo>
    <static>False</static>
    <turnGravityOff>True</turnGravityOff>
  </gazebo>
  <gazebo reference="base_link">
    <selfCollide>True</selfCollide>
    <static>False</static>
    <turnGravityOff>True</turnGravityOff>
  </gazebo>
  <gazebo reference="Right_Thumb_Basecover">
    <selfCollide>True</selfCollide>
    <static>False</static>
    <turnGravityOff>True</turnGravityOff>
    <mu1>0.2</mu1>
    <mu2>0.2</mu2>
  </gazebo>
  <gazebo reference="Right_Thumb_Phoaprox">
    <selfCollide>True</selfCollide>
    <static>False</static>
    <turnGravityOff>True</turnGravityOff>
  </gazebo>
  <gazebo reference="Right_Thumb_Phamed">
    <selfCollide>True</selfCollide>
    <static>False</static>
    <turnGravityOff>True</turnGravityOff>
  </gazebo>
  <gazebo reference="Right_Thumb_Phadist">
    <selfCollide>True</selfCollide>
    <static>False</static>
    <turnGravityOff>True</turnGravityOff>
  </gazebo>
  <!--    <gazebo reference="Right_Index_Basecover">-->
  <!--        <selfCollide>${selfCollideValue}</selfCollide>-->
  <!--        <static>${staticValue}</static>-->
  <!--        <turnGravityOff>${turnGravityOffValue}</turnGravityOff>-->
  <!--    </gazebo>-->
  <!--    <gazebo reference="Right_Index_Phoaprox">-->
  <!--        <selfCollide>${selfCollideValue}</selfCollide>-->
  <!--        <static>${staticValue}</static>-->
  <!--        <turnGravityOff>${turnGravityOffValue}</turnGravityOff>-->
  <!--    </gazebo>-->
  <!--    <gazebo reference="Right_Index_Phamed">-->
  <!--        <selfCollide>${selfCollideValue}</selfCollide>-->
  <!--        <static>${staticValue}</static>-->
  <!--        <turnGravityOff>${turnGravityOffValue}</turnGravityOff>-->
  <!--    </gazebo>-->
  <!--    <gazebo reference="Right_Index_Phadist">-->
  <!--        <selfCollide>${selfCollideValue}</selfCollide>-->
  <!--        <static>${staticValue}</static>-->
  <!--        <turnGravityOff>${turnGravityOffValue}</turnGravityOff>-->
  <!--    </gazebo>-->
  <!--    <gazebo reference="Right_Middle_Basecover">-->
  <!--        <selfCollide>${selfCollideValue}</selfCollide>-->
  <!--        <static>${staticValue}</static>-->
  <!--        <turnGravityOff>${turnGravityOffValue}</turnGravityOff>-->
  <!--    </gazebo>-->
  <!--    <gazebo reference="Right_Middle_Phoaprox">-->
  <!--        <selfCollide>${selfCollideValue}</selfCollide>-->
  <!--        <static>${staticValue}</static>-->
  <!--        <turnGravityOff>${turnGravityOffValue}</turnGravityOff>-->
  <!--    </gazebo>-->
  <!--    <gazebo reference="Right_Middle_Phamed">-->
  <!--        <selfCollide>${selfCollideValue}</selfCollide>-->
  <!--        <static>${staticValue}</static>-->
  <!--        <turnGravityOff>${turnGravityOffValue}</turnGravityOff>-->
  <!--    </gazebo>-->
  <!--    <gazebo reference="Right_Middle_Phadist">-->
  <!--        <selfCollide>${selfCollideValue}</selfCollide>-->
  <!--        <static>${staticValue}</static>-->
  <!--        <turnGravityOff>${turnGravityOffValue}</turnGravityOff>-->
  <!--    </gazebo>-->
  <!--    <gazebo reference="Right_Ring_Basecover">-->
  <!--        <selfCollide>${selfCollideValue}</selfCollide>-->
  <!--        <static>${staticValue}</static>-->
  <!--        <turnGravityOff>${turnGravityOffValue}</turnGravityOff>-->
  <!--    </gazebo>-->
  <!--    <gazebo reference="Right_Ring_Phoaprox">-->
  <!--        <selfCollide>${selfCollideValue}</selfCollide>-->
  <!--        <static>${staticValue}</static>-->
  <!--        <turnGravityOff>${turnGravityOffValue}</turnGravityOff>-->
  <!--    </gazebo>-->
  <!--    <gazebo reference="Right_Ring_Phamed">-->
  <!--        <selfCollide>${selfCollideValue}</selfCollide>-->
  <!--        <static>${staticValue}</static>-->
  <!--        <turnGravityOff>${turnGravityOffValue}</turnGravityOff>-->
  <!--    </gazebo>-->
  <!--    <gazebo reference="Right_Ring_Phadist">-->
  <!--        <selfCollide>${selfCollideValue}</selfCollide>-->
  <!--        <static>${staticValue}</static>-->
  <!--        <turnGravityOff>${turnGravityOffValue}</turnGravityOff>-->
  <!--    </gazebo>-->
  <!--    <gazebo reference="Right_Little_Basecover">-->
  <!--        <selfCollide>${selfCollideValue}</selfCollide>-->
  <!--        <static>${staticValue}</static>-->
  <!--        <turnGravityOff>${turnGravityOffValue}</turnGravityOff>-->
  <!--    </gazebo>-->
  <!--    <gazebo reference="Right_Little_Phoaprox">-->
  <!--        <selfCollide>${selfCollideValue}</selfCollide>-->
  <!--        <static>${staticValue}</static>-->
  <!--        <turnGravityOff>${turnGravityOffValue}</turnGravityOff>-->
  <!--    </gazebo>-->
  <!--    <gazebo reference="Right_Little_Phamed">-->
  <!--        <selfCollide>${selfCollideValue}</selfCollide>-->
  <!--        <static>${staticValue}</static>-->
  <!--        <turnGravityOff>${turnGravityOffValue}</turnGravityOff>-->
  <!--    </gazebo>-->
  <!--    <gazebo reference="Right_Little_Phadist">-->
  <!--        <selfCollide>${selfCollideValue}</selfCollide>-->
  <!--        <static>${staticValue}</static>-->
  <!--        <turnGravityOff>${turnGravityOffValue}</turnGravityOff>-->
  <!--    </gazebo>-->
  <link name="world"/>
  <joint name="fixed" type="fixed">
    <parent link="world"/>
    <child link="base_link"/>
  </joint>
  <link name="base_link">
    <inertial>
      <origin rpy="0 0 0" xyz="0.0 0.0 0.0"/>
      <mass value="1.0"/>
      <inertia ixx="1.0" ixy="0.0" ixz="0.0" iyy="1.0" iyz="0.0" izz="1.0"/>
    </inertial>
    <visual>
      <origin rpy="0 0 0" xyz="0 0 0"/>
      <geometry>
        <mesh filename="package://hithand_description/meshes/visual/hit-hand-2-palm-right.dae"/>
      </geometry>
      <material name="grey"/>
    </visual>
    <collision>
      <origin rpy="0 0 0" xyz="0 0 0"/>
      <geometry name="hithand_right_palm_collision">
        <cylinder length="0.001" radius="0.001"/>
      </geometry>
    </collision>
  </link>
  

+
    
  <!-- #########################fINGER######################## -->
  <link name="Right_Thumb_Basecover">
    <inertial>
      <origin rpy="0 0 0" xyz="0 0 0"/>
      <mass value="1.0"/>
      <inertia ixx="1.0" ixy="0.0" ixz="0.0" iyy="1.0" iyz="0.0" izz="1.0"/>
    </inertial>
    <visual>
      <origin rpy="0 0 0" xyz="0 0 0"/>
      <geometry>
        <!-- <mesh filename="file://$(arg meshDirectory)visual/hit-hand-2-finger-basecover.dae" /> -->
        <mesh filename="package://hithand_description/meshes/visual/hit-hand-2-finger-basecover.dae"/>
      </geometry>
      <material name="white"/>
    </visual>
    <collision>
      <origin rpy="0 0 0" xyz="0 0 0"/>
      <geometry name="hithand_Thumb_base_cover">
        <cylinder length="0.001" radius="0.001"/>
      </geometry>
      <surface>
        <friction>
          <ode>
            <mu>0.6</mu>
            <mu2>0.6</mu2>
          </ode>
        </friction>
      </surface>
    </collision>
  </link>
  <joint name="Right_Thumb_1" type="revolute">
    <!-- joint origin in parent link frame -->
    <origin rpy="0.225810 -1.083656 0.411355" xyz="0.06217593 0.044372912 0.078734808"/>
    <parent link="base_link"/>
    <child link="Right_Thumb_Basecover"/>
    <axis xyz="0 0 1"/>
    <limit effort="1000" lower="-0.50" upper="1.4" velocity="3.14"/>
    <dynamics damping="0.7" friction="0.5"/>
  </joint>
  <link name="Right_Thumb_Phoaprox">
    <inertial>
      <origin rpy="0.225810 -1.083656 0.411355" xyz="0.06217593 0.044372912 0.078734808"/>
      <mass value="1.0"/>
      <inertia ixx="1.0" ixy="0.0" ixz="0.0" iyy="1.0" iyz="0.0" izz="1.0"/>
    </inertial>
    <visual>
      <origin rpy="0 0 0" xyz="0 0 0"/>
      <geometry>
        <mesh filename="package://hithand_description/meshes/visual/hit-hand-2-finger-phaprox.dae"/>
      </geometry>
      <material name="lightblue"/>
    </visual>
    <collision>
      <origin rpy="0 0 0" xyz="0.03 0 0"/>
      <geometry name="hithand_Thumb_phoarpox">
        <box size="0.03 0.03 0.02"/>
      </geometry>
      <surface>
        <friction>
          <ode>
            <mu>0.6</mu>
            <mu2>0.6</mu2>
          </ode>
        </friction>
      </surface>
    </collision>
  </link>
  <joint name="Right_Thumb_2" type="revolute">
    <origin rpy="1.5708 0 0" xyz="0 0 0 "/>
    <parent link="Right_Thumb_Basecover"/>
    <child link="Right_Thumb_Phoaprox"/>
    <axis xyz="0 0 1"/>
    <limit effort="1000" lower="-0.50" upper="1.4" velocity="3.14"/>
    <dynamics damping="0.7" friction="0.5"/>
  </joint>
  <link name="Right_Thumb_Phamed">
    <inertial>
      <origin rpy="0 0 0" xyz="0 0 0"/>
      <mass value="1.0"/>
      <inertia ixx="1.0" ixy="0.0" ixz="0.0" iyy="1.0" iyz="0.0" izz="1.0"/>
    </inertial>
    <visual>
      <origin rpy="0 0 0" xyz="0 0 0"/>
      <geometry>
        <mesh filename="package://hithand_description/meshes/visual/hit-hand-2-finger-phamed.dae"/>
      </geometry>
      <material name="white"/>
    </visual>
    <collision>
      <origin rpy="0 0 0" xyz="0.01 0 0"/>
      <geometry name="hithand_Thumb_phamed">
        <box size="0.01 0.02 0.02"/>
      </geometry>
      <surface>
        <friction>
          <ode>
            <mu>0.6</mu>
            <mu2>0.6</mu2>
          </ode>
        </friction>
      </surface>
    </collision>
  </link>
  <joint name="Right_Thumb_3" type="revolute">
    <origin rpy="0 0 0" xyz="0.055 0 0"/>
    <parent link="Right_Thumb_Phoaprox"/>
    <child link="Right_Thumb_Phamed"/>
    <axis xyz="0 0 1"/>
    <limit effort="1000" lower="-0.50" upper="1.4" velocity="3.14"/>
    <dynamics damping="0.7" friction="0.5"/>
  </joint>
  <link name="Right_Thumb_Phadist">
    <inertial>
      <origin rpy="0 0 0" xyz="0 0 0"/>
      <mass value="1.0"/>
      <inertia ixx="1.0" ixy="0.0" ixz="0.0" iyy="1.0" iyz="0.0" izz="1.0"/>
    </inertial>
    <visual>
      <origin rpy="0 0 0" xyz="0 0 0"/>
      <geometry>
        <mesh filename="package://hithand_description/meshes/visual/hit-hand-2-finger-phadist.dae"/>
      </geometry>
      <material name="lightblue"/>
    </visual>
    <collision>
      <origin rpy="0 0 0" xyz="0 0 0"/>
      <geometry name="hithand_Thumb_phadist">
        <mesh filename="package://hithand_description/meshes/visual/hit-hand-2-finger-phadist.dae"/>
      </geometry>
      <surface>
        <friction>
          <ode>
            <mu>0.6</mu>
            <mu2>0.6</mu2>
          </ode>
        </friction>
      </surface>
    </collision>
  </link>
  <joint name="Right_Thumb_4" type="revolute">
    <origin rpy="0 0 -1.57" xyz="0.025 0 0"/>
    <parent link="Right_Thumb_Phamed"/>
    <child link="Right_Thumb_Phadist"/>
    <axis xyz="0 0 1"/>
    <limit effort="1000" lower="-0.50" upper="1.4" velocity="3.14"/>
    <dynamics damping="0.7" friction="0.5"/>
  </joint>
  <!--    <xacro:finger prefix="Index"  >-->
  <!--        <origin xyz="-0.002529881 0.03680013 0.107783545"-->
  <!--      		rpy="3.054326 -1.570796 0.000000" />-->
  <!--    </xacro:finger>-->
  <!--    <xacro:finger prefix="Middle"  >-->
  <!--            <origin xyz="-0.0037 0.01  0.117783545"-->
  <!--      		rpy="-3.141593 -1.570796 0.000000" />-->
  <!--    </xacro:finger>-->
  <!--    <xacro:finger prefix="Ring"   >-->
  <!--            <origin xyz="0 -0.01680013 0.11258354"-->
  <!--            rpy="-3.054326 -1.570796 0.000000" />-->
  <!--    </xacro:finger>-->
  <!--    <xacro:finger prefix="Little"  >-->
  <!--            <origin xyz="0.000971571 -0.0433963 0.093583545"-->
  <!--            rpy="-2.967060 -1.570796 0.000000" />-->
  <!--    </xacro:finger>-->
</robot>

